 Here's a complete JUnit test case for the given deinit() method, covering the try and catch blocks for code coverage:

```java
import org.junit.Test;
import static org.junit.Assert.*;

public class DeinitTest {

  @Test
  public void testDeinitWithStateNotZero() {
    // Arrange
    YourClassUnderTest objectUnderTest = new YourClassUnderTest();
    objectUnderTest.setState(1); // Set the state to a non-zero value

    // Act
    int result = objectUnderTest.deinit();

    // Assert
    assertEquals(0, result);
    assertEquals(0, objectUnderTest.getState()); // State should be reset to 0
  }

  @Test
  public void testDeinitWithStateZero() {
    // Arrange
    YourClassUnderTest objectUnderTest = new YourClassUnderTest();
    objectUnderTest.setState(0); // Set the state to zero

    // Act
    int result = objectUnderTest.deinit();

    // Assert
    assertEquals(0, result);
    assertEquals(0, objectUnderTest.getState()); // State should remain 0
  }

  @Test
  public void testDeinitWithException() {
    // Arrange
    YourClassUnderTest objectUnderTest = new YourClassUnderTest();
    objectUnderTest.setState(1); // Set the state to a non-zero value
    objectUnderTest.setMockLogger(new MockLogger()); // Set a mock logger that throws an exception

    // Act
    int result = objectUnderTest.deinit();

    // Assert
    assertEquals(0, result);
    assertEquals(0, objectUnderTest.getState()); // State should be reset to 0
    // Verify that the logger captured the exception
    assertTrue(objectUnderTest.getMockLogger().hasErrorLogged());
  }
}
```
In this test case, we have covered three scenarios: deinit() method called with state not equal to zero, deinit() method called with state equal to zero, and deinit() method throwing an exception during the process. We have used a mock logger to simulate the exception in the third scenario. The test case assures complete code coverage of the try and catch blocks in the deinit() method.